Changed directory to /rds/user/mrn31/hpc-work/euler/runs/scaling_runs.

JobID: 17530946
======
Time: Fri  7 Apr 20:40:28 BST 2023
Running on master node: cpu-e-631
Current directory: /rds/user/mrn31/hpc-work/euler/runs/scaling_runs

Nodes allocated:
================
cpu-e-631

numtasks=32, numnodes=1, mpi_tasks_per_node=32 (OMP_NUM_THREADS=1)

Executing command:
==================
mpirun -ppn 32 -np 32  

/home/mrn31/.conda/envs/kwant/lib/python3.8/site-packages/kwant/solvers/default.py:16: RuntimeWarning: MUMPS is not available, SciPy built-in solver will be used as a fallback. Performance can be very poor in this case.
  warnings.warn("MUMPS is not available, "
concurrent.futures.process._RemoteTraceback: 
"""
Traceback (most recent call last):
  File "/home/mrn31/.conda/envs/kwant/lib/python3.8/concurrent/futures/process.py", line 239, in _process_worker
    r = call_item.fn(*call_item.args, **call_item.kwargs)
  File "/home/mrn31/.conda/envs/kwant/lib/python3.8/concurrent/futures/process.py", line 198, in _process_chunk
    return [fn(*args) for args in chunk]
  File "/home/mrn31/.conda/envs/kwant/lib/python3.8/concurrent/futures/process.py", line 198, in <listcomp>
    return [fn(*args) for args in chunk]
  File "./par_Kagome_Gauss_L75.py", line 289, in cluster_run
    with open(file_name, "x") as file_fd:
FileExistsError: [Errno 17] File exists: '../data/scaling/Euler_DOS_dis_full_0.0_tNNN_1.0_L_75.dat'
"""

The above exception was the direct cause of the following exception:

Traceback (most recent call last):
  File "./par_Kagome_Gauss_L75.py", line 408, in <module>
    main()
  File "./par_Kagome_Gauss_L75.py", line 399, in main
    for result in results:
  File "/home/mrn31/.conda/envs/kwant/lib/python3.8/concurrent/futures/process.py", line 484, in _chain_from_iterable_of_lists
    for element in iterable:
  File "/home/mrn31/.conda/envs/kwant/lib/python3.8/concurrent/futures/_base.py", line 611, in result_iterator
    yield fs.pop().result()
  File "/home/mrn31/.conda/envs/kwant/lib/python3.8/concurrent/futures/_base.py", line 432, in result
    return self.__get_result()
  File "/home/mrn31/.conda/envs/kwant/lib/python3.8/concurrent/futures/_base.py", line 388, in __get_result
    raise self._exception
FileExistsError: [Errno 17] File exists: '../data/scaling/Euler_DOS_dis_full_0.0_tNNN_1.0_L_75.dat'
