Changed directory to /rds/user/mrn31/hpc-work/euler/runs.

JobID: 58471614
======
Time: Tue  5 Apr 22:13:21 BST 2022
Running on master node: cpu-e-385
Current directory: /rds/user/mrn31/hpc-work/euler/runs

Nodes allocated:
================
cpu-e-385

numtasks=32, numnodes=1, mpi_tasks_per_node=32 (OMP_NUM_THREADS=1)

Executing command:
==================
mpirun -ppn 32 -np 32  

/home/mrn31/.conda/envs/kwant/lib/python3.8/site-packages/kwant/solvers/default.py:16: RuntimeWarning: MUMPS is not available, SciPy built-in solver will be used as a fallback. Performance can be very poor in this case.
  warnings.warn("MUMPS is not available, "
Traceback (most recent call last):
  File "./parallel_dis_N3kag_Gaus_150.py", line 345, in <module>
    main()
  File "./parallel_dis_N3kag_Gaus_150.py", line 336, in main
    for result in results:
  File "/home/mrn31/.conda/envs/kwant/lib/python3.8/concurrent/futures/process.py", line 484, in _chain_from_iterable_of_lists
    for element in iterable:
  File "/home/mrn31/.conda/envs/kwant/lib/python3.8/concurrent/futures/_base.py", line 611, in result_iterator
    yield fs.pop().result()
  File "/home/mrn31/.conda/envs/kwant/lib/python3.8/concurrent/futures/_base.py", line 439, in result
    return self.__get_result()
  File "/home/mrn31/.conda/envs/kwant/lib/python3.8/concurrent/futures/_base.py", line 388, in __get_result
    raise self._exception
concurrent.futures.process.BrokenProcessPool: A process in the process pool was terminated abruptly while the future was running or pending.
